[2024-11-24T14:28:12.724+0200] {local_task_job_runner.py:123} INFO - ::group::Pre task execution logs
[2024-11-24T14:28:12.748+0200] {taskinstance.py:2613} INFO - Dependencies all met for dep_context=non-requeueable deps ti=<TaskInstance: continuous_patient_data_generation.trigger_dag_run scheduled__2024-11-24T12:27:00+00:00 [queued]>
[2024-11-24T14:28:12.763+0200] {taskinstance.py:2613} INFO - Dependencies all met for dep_context=requeueable deps ti=<TaskInstance: continuous_patient_data_generation.trigger_dag_run scheduled__2024-11-24T12:27:00+00:00 [queued]>
[2024-11-24T14:28:12.763+0200] {taskinstance.py:2866} INFO - Starting attempt 1 of 2
[2024-11-24T14:28:12.785+0200] {taskinstance.py:2889} INFO - Executing <Task(PythonOperator): trigger_dag_run> on 2024-11-24 12:27:00+00:00
[2024-11-24T14:28:12.792+0200] {standard_task_runner.py:72} INFO - Started process 489292 to run task
[2024-11-24T14:28:12.798+0200] {standard_task_runner.py:104} INFO - Running: ['airflow', 'tasks', 'run', 'continuous_patient_data_generation', 'trigger_dag_run', 'scheduled__2024-11-24T12:27:00+00:00', '--job-id', '13', '--raw', '--subdir', 'DAGS_FOLDER/real_time_patient_data_update.py', '--cfg-path', '/tmp/tmp3ycuzptf']
[2024-11-24T14:28:12.802+0200] {standard_task_runner.py:105} INFO - Job 13: Subtask trigger_dag_run
[2024-11-24T14:28:12.860+0200] {task_command.py:467} INFO - Running <TaskInstance: continuous_patient_data_generation.trigger_dag_run scheduled__2024-11-24T12:27:00+00:00 [running]> on host munyah-ThinkPad-X1-Yoga-1st
[2024-11-24T14:28:12.953+0200] {taskinstance.py:3132} INFO - Exporting env vars: AIRFLOW_CTX_DAG_OWNER='airflow' AIRFLOW_CTX_DAG_ID='continuous_patient_data_generation' AIRFLOW_CTX_TASK_ID='trigger_dag_run' AIRFLOW_CTX_EXECUTION_DATE='2024-11-24T12:27:00+00:00' AIRFLOW_CTX_TRY_NUMBER='1' AIRFLOW_CTX_DAG_RUN_ID='scheduled__2024-11-24T12:27:00+00:00'
[2024-11-24T14:28:12.954+0200] {logging_mixin.py:190} INFO - Task instance is in running state
[2024-11-24T14:28:12.955+0200] {logging_mixin.py:190} INFO -  Previous state of the Task instance: queued
[2024-11-24T14:28:12.955+0200] {logging_mixin.py:190} INFO - Current task name:trigger_dag_run state:running start_date:2024-11-24 12:28:12.748954+00:00
[2024-11-24T14:28:12.955+0200] {logging_mixin.py:190} INFO - Dag name:continuous_patient_data_generation and current dag run status:running
[2024-11-24T14:28:12.955+0200] {taskinstance.py:731} INFO - ::endgroup::
[2024-11-24T14:28:12.963+0200] {taskinstance.py:3311} ERROR - Task failed with exception
Traceback (most recent call last):
  File "/home/munyah/.local/lib/python3.10/site-packages/airflow/models/taskinstance.py", line 767, in _execute_task
    result = _execute_callable(context=context, **execute_callable_kwargs)
  File "/home/munyah/.local/lib/python3.10/site-packages/airflow/models/taskinstance.py", line 733, in _execute_callable
    return ExecutionCallableRunner(
  File "/home/munyah/.local/lib/python3.10/site-packages/airflow/utils/operator_helpers.py", line 252, in run
    return self.func(*args, **kwargs)
  File "/home/munyah/.local/lib/python3.10/site-packages/airflow/models/baseoperator.py", line 417, in wrapper
    return func(self, *args, **kwargs)
  File "/home/munyah/.local/lib/python3.10/site-packages/airflow/operators/python.py", line 238, in execute
    return_value = self.execute_callable()
  File "/home/munyah/.local/lib/python3.10/site-packages/airflow/operators/python.py", line 256, in execute_callable
    return runner.run(*self.op_args, **self.op_kwargs)
  File "/home/munyah/.local/lib/python3.10/site-packages/airflow/utils/operator_helpers.py", line 252, in run
    return self.func(*args, **kwargs)
  File "/home/munyah/airflow/dags/real_time_patient_data_update.py", line 86, in trigger_dag_run
    trigger = TriggerDagRunOperator(
  File "/home/munyah/.local/lib/python3.10/site-packages/airflow/models/baseoperator.py", line 501, in apply_defaults
    result = func(self, **kwargs, default_args=default_args)
  File "/home/munyah/.local/lib/python3.10/site-packages/airflow/operators/trigger_dagrun.py", line 145, in __init__
    super().__init__(**kwargs)
  File "/home/munyah/.local/lib/python3.10/site-packages/airflow/models/baseoperator.py", line 501, in apply_defaults
    result = func(self, **kwargs, default_args=default_args)
  File "/home/munyah/.local/lib/python3.10/site-packages/airflow/models/baseoperator.py", line 967, in __init__
    task_group.add(self)
  File "/home/munyah/.local/lib/python3.10/site-packages/airflow/utils/task_group.py", line 250, in add
    raise DuplicateTaskIdFound(f"{node_type} id '{key}' has already been added to the DAG")
airflow.exceptions.DuplicateTaskIdFound: Task id 'trigger_dag_run' has already been added to the DAG
[2024-11-24T14:28:12.971+0200] {logging_mixin.py:190} INFO - Task instance in failure state
[2024-11-24T14:28:12.972+0200] {logging_mixin.py:190} INFO - Task start:2024-11-24 12:28:12.748954+00:00 end:2024-11-24 12:28:12.971187+00:00 duration:0.222233
[2024-11-24T14:28:12.972+0200] {logging_mixin.py:190} INFO - Task:<Task(PythonOperator): trigger_dag_run> dag:<DAG: continuous_patient_data_generation> dagrun:<DagRun continuous_patient_data_generation @ 2024-11-24 12:27:00+00:00: scheduled__2024-11-24T12:27:00+00:00, state:running, queued_at: 2024-11-24 12:28:01.345525+00:00. externally triggered: False>
[2024-11-24T14:28:12.973+0200] {logging_mixin.py:190} INFO - Failure caused by Task id 'trigger_dag_run' has already been added to the DAG
[2024-11-24T14:28:12.973+0200] {taskinstance.py:1225} INFO - Marking task as UP_FOR_RETRY. dag_id=continuous_patient_data_generation, task_id=trigger_dag_run, run_id=scheduled__2024-11-24T12:27:00+00:00, execution_date=20241124T122700, start_date=20241124T122812, end_date=20241124T122812
[2024-11-24T14:28:12.988+0200] {taskinstance.py:340} INFO - ::group::Post task execution logs
[2024-11-24T14:28:12.988+0200] {standard_task_runner.py:124} ERROR - Failed to execute job 13 for task trigger_dag_run (Task id 'trigger_dag_run' has already been added to the DAG; 489292)
Traceback (most recent call last):
  File "/home/munyah/.local/lib/python3.10/site-packages/airflow/task/task_runner/standard_task_runner.py", line 117, in _start_by_fork
    ret = args.func(args, dag=self.dag)
  File "/home/munyah/.local/lib/python3.10/site-packages/airflow/cli/cli_config.py", line 49, in command
    return func(*args, **kwargs)
  File "/home/munyah/.local/lib/python3.10/site-packages/airflow/utils/cli.py", line 116, in wrapper
    return f(*args, **kwargs)
  File "/home/munyah/.local/lib/python3.10/site-packages/airflow/cli/commands/task_command.py", line 483, in task_run
    task_return_code = _run_task_by_selected_method(args, _dag, ti)
  File "/home/munyah/.local/lib/python3.10/site-packages/airflow/cli/commands/task_command.py", line 256, in _run_task_by_selected_method
    return _run_raw_task(args, ti)
  File "/home/munyah/.local/lib/python3.10/site-packages/airflow/cli/commands/task_command.py", line 341, in _run_raw_task
    return ti._run_raw_task(
  File "/home/munyah/.local/lib/python3.10/site-packages/airflow/utils/session.py", line 97, in wrapper
    return func(*args, session=session, **kwargs)
  File "/home/munyah/.local/lib/python3.10/site-packages/airflow/models/taskinstance.py", line 3005, in _run_raw_task
    return _run_raw_task(
  File "/home/munyah/.local/lib/python3.10/site-packages/airflow/models/taskinstance.py", line 273, in _run_raw_task
    TaskInstance._execute_task_with_callbacks(
  File "/home/munyah/.local/lib/python3.10/site-packages/airflow/models/taskinstance.py", line 3159, in _execute_task_with_callbacks
    result = self._execute_task(context, task_orig)
  File "/home/munyah/.local/lib/python3.10/site-packages/airflow/models/taskinstance.py", line 3183, in _execute_task
    return _execute_task(self, context, task_orig)
  File "/home/munyah/.local/lib/python3.10/site-packages/airflow/models/taskinstance.py", line 767, in _execute_task
    result = _execute_callable(context=context, **execute_callable_kwargs)
  File "/home/munyah/.local/lib/python3.10/site-packages/airflow/models/taskinstance.py", line 733, in _execute_callable
    return ExecutionCallableRunner(
  File "/home/munyah/.local/lib/python3.10/site-packages/airflow/utils/operator_helpers.py", line 252, in run
    return self.func(*args, **kwargs)
  File "/home/munyah/.local/lib/python3.10/site-packages/airflow/models/baseoperator.py", line 417, in wrapper
    return func(self, *args, **kwargs)
  File "/home/munyah/.local/lib/python3.10/site-packages/airflow/operators/python.py", line 238, in execute
    return_value = self.execute_callable()
  File "/home/munyah/.local/lib/python3.10/site-packages/airflow/operators/python.py", line 256, in execute_callable
    return runner.run(*self.op_args, **self.op_kwargs)
  File "/home/munyah/.local/lib/python3.10/site-packages/airflow/utils/operator_helpers.py", line 252, in run
    return self.func(*args, **kwargs)
  File "/home/munyah/airflow/dags/real_time_patient_data_update.py", line 86, in trigger_dag_run
    trigger = TriggerDagRunOperator(
  File "/home/munyah/.local/lib/python3.10/site-packages/airflow/models/baseoperator.py", line 501, in apply_defaults
    result = func(self, **kwargs, default_args=default_args)
  File "/home/munyah/.local/lib/python3.10/site-packages/airflow/operators/trigger_dagrun.py", line 145, in __init__
    super().__init__(**kwargs)
  File "/home/munyah/.local/lib/python3.10/site-packages/airflow/models/baseoperator.py", line 501, in apply_defaults
    result = func(self, **kwargs, default_args=default_args)
  File "/home/munyah/.local/lib/python3.10/site-packages/airflow/models/baseoperator.py", line 967, in __init__
    task_group.add(self)
  File "/home/munyah/.local/lib/python3.10/site-packages/airflow/utils/task_group.py", line 250, in add
    raise DuplicateTaskIdFound(f"{node_type} id '{key}' has already been added to the DAG")
airflow.exceptions.DuplicateTaskIdFound: Task id 'trigger_dag_run' has already been added to the DAG
[2024-11-24T14:28:13.012+0200] {local_task_job_runner.py:266} INFO - Task exited with return code 1
[2024-11-24T14:28:13.031+0200] {taskinstance.py:3895} INFO - 0 downstream tasks scheduled from follow-on schedule check
[2024-11-24T14:28:13.032+0200] {local_task_job_runner.py:245} INFO - ::endgroup::
